I'm sorry, but an uncaught exception occurred.

While running game code:
  File "game/script.rpy", line 279, in script call
    call decryption("este es el mensaje")
  File "game/decryption_minigame/decryption_main.rpy", line 14, in <module>
  File "game/decryption_minigame/d_python_functions.rpy", line 51, in DetermineKeyOrder
ValueError: '\xa0' is not in list

-- Full Traceback ------------------------------------------------------------

Full traceback:
  File "game/script.rpy", line 279, in script call
    call decryption("este es el mensaje")
  File "game/decryption_minigame_scripts/decryption_main.rpyc", line 13, in script
  File "C:\Users\barba\OneDrive\Escritorio\renpy-8.3.2\renpy\ast.py", line 821, in execute
    renpy.python.py_exec_bytecode(self.code.bytecode, self.hide, store=self.store)
  File "C:\Users\barba\OneDrive\Escritorio\renpy-8.3.2\renpy\python.py", line 1178, in py_exec_bytecode
    exec(bytecode, globals, locals)
  File "game/decryption_minigame/decryption_main.rpy", line 14, in <module>
  File "game/decryption_minigame/d_python_functions.rpy", line 51, in DetermineKeyOrder
ValueError: '\xa0' is not in list

Windows-10-10.0.22631 AMD64
Ren'Py 8.3.2.24090902
NCRPTD_Productions_Mecanicas_Renpy 1.0
Fri Nov  1 00:07:32 2024
